<?xml version="1.0"?>
<robot name="quadruped">
    
    <!-- Base (Main Body) -->
    <link name="base">
        <inertial>
            <mass value="5"/>
            <origin xyz="0 0 0"/>
            <inertia ixx="0.1" ixy="0" ixz="0" iyy="0.1" iyz="0" izz="0.1"/>
        </inertial>
        <visual>
            <origin xyz="0 0 0"/>
            <geometry>
                <box size="0.4 0.2 0.1"/>
            </geometry>
        </visual>
        <collision>
            <origin xyz="0 0 0"/>
            <geometry>
                <box size="0.4 0.2 0.1"/>
            </geometry>
        </collision>
    </link>

    <!-- Legs (Four simple legs) -->
    <joint name="front_left_hip" type="revolute">
        <parent link="base"/>
        <child link="front_left_leg"/>
        <origin xyz="0.2 0.1 0"/>
        <axis xyz="0 1 0"/>
        <limit lower="-0.5" upper="0.5" effort="1" velocity="1"/>
    </joint>
    <link name="front_left_leg">
        <visual>
            <origin xyz="0 -0.05 -0.15"/>
            <geometry>
                <cylinder radius="0.02" length="0.3"/>
            </geometry>
        </visual>
        <collision>
            <origin xyz="0 -0.05 -0.15"/>
            <geometry>
                <cylinder radius="0.02" length="0.3"/>
            </geometry>
        </collision>
    </link>

    <joint name="front_right_hip" type="revolute">
        <parent link="base"/>
        <child link="front_right_leg"/>
        <origin xyz="0.2 -0.1 0"/>
        <axis xyz="0 1 0"/>
        <limit lower="-0.5" upper="0.5" effort="1" velocity="1"/>
    </joint>
    <link name="front_right_leg">
        <visual>
            <origin xyz="0 -0.05 -0.15"/>
            <geometry>
                <cylinder radius="0.02" length="0.3"/>
            </geometry>
        </visual>
        <collision>
            <origin xyz="0 -0.05 -0.15"/>
            <geometry>
                <cylinder radius="0.02" length="0.3"/>
            </geometry>
        </collision>
    </link>

    <joint name="back_left_hip" type="revolute">
        <parent link="base"/>
        <child link="back_left_leg"/>
        <origin xyz="-0.2 0.1 0"/>
        <axis xyz="0 1 0"/>
        <limit lower="-0.5" upper="0.5" effort="1" velocity="1"/>
    </joint>
    <link name="back_left_leg">
        <visual>
            <origin xyz="0 -0.05 -0.15"/>
            <geometry>
                <cylinder radius="0.02" length="0.3"/>
            </geometry>
        </visual>
        <collision>
            <origin xyz="0 -0.05 -0.15"/>
            <geometry>
                <cylinder radius="0.02" length="0.3"/>
            </geometry>
        </collision>
    </link>

    <joint name="back_right_hip" type="revolute">
        <parent link="base"/>
        <child link="back_right_leg"/>
        <origin xyz="-0.2 -0.1 0"/>
        <axis xyz="0 1 0"/>
        <limit lower="-0.5" upper="0.5" effort="1" velocity="1"/>
    </joint>
    <link name="back_right_leg">
        <visual>
            <origin xyz="0 -0.05 -0.15"/>
            <geometry>
                <cylinder radius="0.02" length="0.3"/>
            </geometry>
        </visual>
        <collision>
            <origin xyz="0 -0.05 -0.15"/>
            <geometry>
                <cylinder radius="0.02" length="0.3"/>
            </geometry>
        </collision>
    </link>

</robot>